Workbook

Sheet 도로교시방서
A1: 설계 기준(한국 도로교 시방서)
B3: 해설 표 2.11.1 | D3: 지역별 기본풍속
B4: 구 분 | C4: 지 역 | D4: 지 명 | G4: 기본 풍속(m/s)
B5: I | C5: 내륙 | D5: 서울, 대구, 대전, 춘천, 청주, 수원 추풍령, 전주, 이리, 진주, 광주 | G5: 30
B6: II | C6: 서해안 | D6: 서산, 인천 | G6: 35
B7: III | C7: 서남해안 남해안 동남해안 | D7: 군산, 여수, 충무, 부산, 포항, 울산 | G7: 40
B8: IV | C8: 동해안 제주지역 특수지역 | D8: 속초, 강릉, 제주, 서귀포, 목포 | G8: 45
B9: V | D9: 울릉도 | G9: 50
B11: 해설 표 2.11.2 | D11: 지표조도구분에 의한 α, ZG, Zb 의 값
B12: 구 분 | C12: 지표 상황 | F12: α | G12: ZG(m) | H12: Zb(m) | I12: 조도
B13: I | C13: 해상, 해안 | F13: 0.12 | G13: 500 | H13: 5 | I13: 작다
B14: II | C14: 개활지, 농지, 전원 수목과저층건축물이 산재하여 있는 지역 | F14: 0.16 | G14: 600 | H14: 10
B15: III | C15: 수목과 저층건축물이밀집하여 있는 지역 중, 고층 건물이산재하여 있는 지역 완만한 구릉지 | F15: 0.22 | G15: 700 | H15: 15
B16: IV | C16: 중, 고층 건물이 밀집하여 있는 지역 기목이 심한 구릉지 | F16: 0.29 | G16: 700 | H16: 30 | I16: 크다
B18: 설계기준풍속(m/s) - 도로교시방서(1996)
B19: Vd = | C19: 1.925(z/zG)αV10 | E19: , z ≥ zb
C20: 1.925(zb/zG)αV10 | E20: , z < zb
A23: 완도대교
B24: 제원
B25: 구 분 | D25: 입 력
B26: 지역구분 | D26: I
B27: 지표조도구분 | D27: IV
B28: 고도(m) | D28: 40
B30: 설계기준풍속
B31: 기본 풍속 | C31: α | D31: ZG(m) | E31: Zb(m) | F31: 설계기준풍속(m/s)
B32: =30*0.93 -> 27.9 | C32: =LOOKUP($D$27,$B$13:$B$16,F13:F16) -> 0.29 | D32: =LOOKUP($D$27,$B$13:$B$16,G13:G16) -> 700 | E32: =LOOKUP($D$27,$B$13:$B$16,H13:H16) -> 30 | F32: =IF(D28>=E32,1.925*(D28/D32)^C32*B32,1.925*(E32/D32)^C32*B32) -> 23.418221

Sheet 일본 도로교 내풍설계편람
A1: 설계 기준(일본 도로교 내풍설계편람)
A2: 1) 기본풍속
B3: 해설 표 2.11.1 | D3: 지역별 기본풍속
B4: 구 분 | C4: 지 역 | D4: 지 명 | G4: 기본 풍속(m/s)
B5: I | C5: 내륙 | D5: 서울, 대구, 대전, 춘천, 청주, 수원 추풍령, 전주, 이리, 진주, 광주 | G5: 30
B6: II | C6: 서해안 | D6: 서산, 인천 | G6: 35
B7: III | C7: 서남해안 남해안 동남해안 | D7: 군산, 여수, 충무, 부산, 포항, 울산 | G7: 40
B8: IV | C8: 동해안 제주지역 특수지역 | D8: 속초, 강릉, 제주, 서귀포, 목포 | G8: 45
B9: V | D9: 울릉도 | G9: 50
A11: 2) 지표조도계수
B12: 표-2.1 | D12: 지표조도계수
B13: 구 분 | C13: 지표 상황 | F13: α | G13: ZG(m) | H13: Zb(m) | I13: 조도
B14: I | C14: 해상, 해안 | F14: 0.12 | G14: 500 | H14: 5 | I14: 작다
B15: II | C15: 개활지, 농지, 전원 수목과저층건축물이 산재하여 있는 지역 | F15: 0.16 | G15: 600 | H15: 10
B16: III | C16: 수목과 저층건축물이밀집하여 있는 지역 중, 고층 건물이산재하여 있는 지역 완만한 구릉지 | F16: 0.22 | G16: 700 | H16: 15
B17: IV | C17: 중, 고층 건물이 밀집하여 있는 지역 기목이 심한 구릉지 | F17: 0.29 | G17: 700 | H17: 30 | I17: 크다
A19: 3) 보정계수 E1
B20: 표-2.2 | C20: 보정계수 E1
B21: 구 분 | C21: I | D21: II | E21: III | F21: IV
B22: -100 | C22: 1.57 | D22: 1.43 | E22: 1.25 | F22: 1.08
B23: -90 | C23: 1.55 | D23: 1.41 | E23: 1.22 | F23: 1.04
B24: -80 | C24: 1.53 | D24: 1.38 | E24: 1.18 | F24: 1
B25: -70 | C25: 1.5 | D25: 1.35 | E25: 1.15 | F25: 0.96
B26: -60 | C26: 1.47 | D26: 1.31 | E26: 1.11 | F26: 0.92
B27: -50 | C27: 1.45 | D27: 1.28 | E27: 1.07 | F27: 0.88
B28: -45 | C28: 1.43 | D28: 1.26 | E28: 1.04 | F28: 0.85
B29: -40 | C29: 1.41 | D29: 1.24 | E29: 1.01 | F29: 0.82
B30: -35 | C30: 1.39 | D30: 1.21 | E30: 0.98 | F30: 0.79
B31: -30 | C31: 1.36 | D31: 1.18 | E31: 0.94 | F31: 0.77
B32: -25 | C32: 1.33 | D32: 1.14 | E32: 0.9 | F32: 0.77
B33: -20 | C33: 1.29 | D33: 1.09 | E33: 0.85 | F33: 0.77
... B36: -5 | C36: 1.11 | D36: 1 | E36: 0.83 | F36: 0.77
A38: 4) 설계기준풍속(m/s)
B39: Ud = | C39: E1*U10
A41: =도로교시방서!A23 -> 완도대교
B42: 제원
B43: 구 분 | D43: 입 력
B44: 지역구분 | D44: =도로교시방서!D26 -> I
B45: 지표조도구분 | D45: =도로교시방서!D27 -> IV
B46: 고도(m) | D46: =도로교시방서!D28 -> 40
...

Sheet 혼슈-시코쿠 기준
A1: 설계 기준(혼슈-시코쿠 기준)
A2: 1) 기본풍속
B3: 해설 표 2.11.1 | D3: 지역별 기본풍속
B4: 구 분 | C4: 지 역 | D4: 지 명 | G4: 기본 풍속(m/s)
B5: I | C5: 내륙 | D5: 서울, 대구, 대전, 춘천, 청주, 수원 추풍령, 전주, 이리, 진주, 광주 | G5: 30
B6: II | C6: 서해안 | D6: 서산, 인천 | G6: 35
B7: III | C7: 서남해안 남해안 동남해안 | D7: 군산, 여수, 충무, 부산, 포항, 울산 | G7: 40
B8: IV | C8: 동해안 제주지역 특수지역 | D8: 속초, 강릉, 제주, 서귀포, 목포 | G8: 45
B9: V | D9: 울릉도 | G9: 50
A11: 2) 고도에 의한 보정계수
B12: 표-2.1 | D12: 고도보정계수 ν1
B13: 고도(m) | C13: ν1 | D13: 수평길이(m) | E13: ν2 | F13: 연직길이(m) | G13: ν3
B14: -200 | C14: 1.53 | D14: -1800 | E14: 1.12 | F14: -260 | G14: 1.17
B15: -180 | C15: 1.51 | D15: -1500 | E15: 1.12 | F15: -200 | G15: 1.17
B16: -160 | C16: 1.49 | D16: -1200 | E16: 1.13 | F16: -160 | G16: 1.18
B17: -140 | C17: 1.46 | D17: -1000 | E17: 1.14 | F17: -120 | G17: 1.19
B18: -120 | C18: 1.43 | D18: -800 | E18: 1.15 | F18: -100 | G18: 1.19
B19: -100 | C19: 1.39 | D19: -650 | E19: 1.16 | F19: -80 | G19: 1.2
B20: -90 | C20: 1.37 | D20: -500 | E20: 1.17
B21: -80 | C21: 1.35 | D21: -400 | E21: 1.18
B22: -70 | C22: 1.32 | D22: -300 | E22: 1.19
B23: -60 | C23: 1.29 | D23: -200 | E23: 1.21
B24: -50 | C24: 1.26
B25: -40 | C25: 1.22
B26: -30 | C26: 1.17
B27: -20 | C27: 1.1
B28: -10 | C28: 1
B30: 3) 설계기준풍속(m/s)
B31: Vd = | C31: ν1*ν2*U10 | D31: ; 수평방향으로 긴 구조물
B32: Vd = | C32: ν1*ν2*U10 | D32: ; 수직방향으로 긴 구조물
B34: =도로교시방서!A23 -> 완도대교
B35: 제원
B36: 구 분 | D36: 입 력
B37: 고도(m) | D37: =도로교시방서!D28 -> 40
B38: 수평길이(m) | D38: 145
B39: 수직길이(m) | D39: 0
B41: 설계기준풍속
B42: 기본풍속 | C42: ν1 | D42: ν2 | E42: ν3 | F42: 설계기준풍속(m/s)
B43: =도로교시방서!B32 -> 27.9 | C43: =LOOKUP(D37*-1,B14:B28,C14:C28) -> 1.22 | D43: =LOOKUP(D38*-1,D14:D23,E14:E23) -> 1.21 | E43: =LOOKUP(D39*-1,F14:F19,G14:G19) -> 1.2 | F43: =IF(D38>D39,C43*D43*B43,C43*E43*B43) -> 41.18598
A46: 참고
...

Sheet 대한건축학회
A1: 설계 기준(대한건축학회 기준)
A2: 1) 기본풍속
B3: 표 5.1 | C3: 지역별 기본풍속(V0)
B4: 구 분 | C4: 지 역 | H4: 기본 풍속(m/s)
B5: 서울, 경기도 | C5: 서울, 인천, 김포, 부천, 부평, 구리, 오산, 송탄, 평택, 시흥, 과천, 안양, 수원, 안산, 군포, 의왕, 안성, 강화 | H5: 30
C6: 양평, 성남, 하남, 용인, 의정부, 동두천, 포천, 파주, 광주, 기흥, 미금, 여주, 이천, 신갈, 장호원 | H6: 25
B7: 강원도 | C7: 속초, 강릉, 양양, 주문진 | H7: 40
C8: 거진, 간성, 동해, 삼척, 원덕 | H8: 35
C9: 춘천, 화천, 양구, 철원, 김화, 인제, 영월, 정선, 태백, 원주, 평창, 홍천 | H9: 25
B10: 충청도 | C10: 장항 | H10: 40
C11: 태안, 서산, 청주, 대천, 서천, 안면도, 조치원, 천안, 홍성, 광천, 아산 | H11: 35
C12: 대전, 당진, 합덕, 성환, 진천, 증평, 온양 | H12: 30
C13: 음성, 청양, 금산, 영동, 공주, 논산, 제천, 충주, 부여, 보은, 단양, 괴산, 옥천 | H13: 25
B14: 경상도 | C14: 포항, 울릉도, 구룡포, 오천, 홍해, 감포 | H14: 45
C15: 부산, 기장, 장안, 연일, 외동, 가덕도 | H15: 40
C16: 울산, 통영, 거제 고성, 진해, 김해, 마산, 창원, 양산, 진영, 울진, 평해, 안강, 경주, 남해, 삼천포 | H16: 35
C17: 건천, 가야, 삼랑진, 영덕, 사천 | H17: 30
C18: 대구, 영주, 구미, 김천, 영천, 안동, 봉화, 풍기, 예천, 청송, 양양, 하양, 경산, 청도, 남지, 의령, 추풍령, 상주, 선산, 군위, 의성, 문경, 점촌, 함창, 진주, 거창, 함양, 산청, 고령, 창녕, 합천, 밀양 | H18: 25
B19: 전라도 | C19: 군산, 미성 | H19: 40
C20: 목포, 여수, 완도, 진도, 옥구, 노화, 익산, 금일, 해남, 관산, 대덕, 도양, 고흥 | H20: 35
C21: 광주, 나주, 화순, 영암, 일노, 강진, 장흥, 보성, 벌교, 순천, 광양, 무안, 함평, 영광 | H21: 30
C22: 전주, 함열, 진안, 무주, 삼레, 담양, 부안, 남원, 순창, 구례, 고창, 정주, 장수, 승주, 임실, 태인 | H22: 25
B23: 제주도 | C23: 전지역 | H23: 40
A25: 2) 풍속의 고도분포계수
B26: 표 5.2 | C26: 노풍도 구분
B27: 노풍도구분 | C27: 주변지역의 지표면 상태
B28: A | C28: 대도시 중심부에서 10층이상의 대규모 고층건물이 밀집해 있는 지역
B29: B | C29: 높이 3.5m 정도의 주택과 같은 건물이밀집해 있는 지역, 중층건물이 산재해 있는 지역
B30: C | C30: 높이 1.5~10m 정도의장애물이 산재해 있는 지역, 저층건물이 산재해 있는 지역
B31: D | C31: 장애물이 거의 없고, 주변 장애물의 평균높이가 1.5m 이하인 지역, 해안, 초원, 비행장
B33: 표 5.3~5.4 | C33: 보정계수
B34: 노풍도구분 | C34: A | D34: B | E34: C | F34: D
B35: Zb(m) | C35: 20 | D35: 15 | E35: 10 | F35: 5
B36: ZG(m) | C36: 500 | D36: 400 | E36: 300 | F36: 250
B37: α | C37: 0.33 | D37: 0.22 | E37: 0.15 | F37: 0.1
B38: Kzr(Z≤Zb) | C38: 0.58 | D38: 0.81 | E38: 1 | F38: 1.13
B39: Kzr(Zb<Z≤ZG) | C39: 0.22Zα | D39: 0.45Zα | E39: 0.71Zα | F39: 0.97Zα
A41: 3) 지형에 의한 풍속할증계수
B42: 표 5.5 | C42: 노풍도 구분
B43: 불리한 경사 | C43: 풍속할증계수(Kzt)
...

Sheet 모형 Setup! (2)
A1: 모형 Set-up! | C1: S = | D1: 1
C2: 형고 | D2: 0.1
B3: 구 분 | C3: 실 교 량 | D3: 단 위 | E3: 모 형 | F3: 단 위 | K3: 실험치 | L3: 목표치 | N3: 무게(kg)
B4: 교폭 | C4: 0.4 | D4: m | E4: =C4*$D$1^-1*100 -> 40 | F4: cm | I4: 모형무게(모형+난간+방호책): | K4: 2.757 | M4: 1/4지점 | N4: 1.417
A5: 3.82 | B5: 질량 | C5: 0.0043729412 | D5: t/m | E5: =C5*$D$1^-2*1000 -> 4.3729412 | F5: kg/m | G5: 회전반경, r | I5: 페어링: | M5: 3/8지점 | N5: 1.751
A6: 6.816 | B6: 질량관성모멘트 | C6: 6.5122042e-05 | D6: t*m2/m | E6: =C6*$D$1^-4*10000000 -> 651.22042 | F6: kg*cm2/m | G6: =SQRT(E6/E5) -> 12.203297 | I6: 지그: | K6: 0.678 | P6: 0.107
B7: 휨 진동수 | C7: 1.4303 | D7: Hz | E7: =C7*SQRT($D$1) -> 1.4303 | F7: Hz | I7: 소계: | K7: =SUM(K4:K6) -> 3.435 | P7: 0.074
B8: 비틀림 진동수 | C8: 3.1036 | D8: Hz | E8: =C8*SQRT($D$1) -> 3.1036 | F8: Hz | I8: 추가질량: | K8: 0.334 | L8: =L9-K9 -> -0.05199998 | P8: 0.315
B9: 감쇠율 | C9: =(0.3/100)*2*PI() -> 0.018849556 | E9: =C9 -> 0.018849556 | I9: 합계: | K9: =K7+K8 -> 3.769 | L9: =L10*0.85 -> 3.717
B10: 풍 속 | C10: =도로교시방서!F32 -> 23.418221 | D10: m/s | E10: =C10*$D$1^(-1/2) -> 23.418221 | F10: m/s | I10: 단위길이당 질량: | K10: =K9/0.85 -> 4.4341176 | L10: =E5 -> 4.3729412 | M10: =((L10-K10)/L10)*100 -> -1.3989771 | N10: 1.4028 | O10: 1.4069 | P10: 1.4
C11: =C10*1.3 -> 30.443687 | E11: =C11*$D$1^(-1/2) -> 30.443687 | I11: SC B | K11: =(2*E5*C9)/(1.225*(E4/100)^2) -> 0.84110204 | N11: 1.7889 | O11: 1.777 | P11: 1.7688
A12: 질량의 조정 & 질량관성모멘트의 조정 | G12: =E4/2 -> 20 | I12: SC T | K12: =(2*E6*C9)/(1.225*(E4/100)^2) -> 125.2573 | L12: 감쇠
B13: 구 분 | D13: 변 수 명 | E13: 값 | F13: 단 위 | L13: 진동모드 | M13: 대상진폭 | N13: 단면1 | O13: 단면2 | P13: 최종
B14: (모형+추가질량)의 질량 | D14: Mo | E14: =E15/(1-(E17/E16)^2)/E18 -> 4.7148934 | F14: kg/m | G14: =E14-E15/E18 -> 4.3219522 | N14: 감쇠율 | O14: 감쇠율 | P14: 감쇠율
B15: 추가 질량 | D15: Ma | E15: =K8 -> 0.334 | F15: kg | L15: 연직 | M15: =E4/200*10 -> 2 | N15: 0.013
B16: 모형의 휨진동수 | D16: Fbo | E16: 1.273 | F16: Hz | L16: 비틀림 | M16: =SIN(RADIANS(0.5))*(E4/2)*10 -> 1.7453071 | N16: 0.0164
B17: 질량 추가시 휨진동수 | D17: Fba | E17: 1.2188 | F17: Hz | M17: =SIN(RADIANS(0.5))*(13)*14 -> 1.5882295 | N17: =N15/(2*PI())*100 -> 0.20690143 | O17: =O15/(2*PI())*100 -> 0 | P17: =P15/(2*PI())*100 -> 0
B18: 모형의 길이 | D18: L | E18: 0.85 | F18: m | N18: =N16/(2*PI())*100 -> 0.26101411 | O18: =O16/(2*PI())*100 -> 0 | P18: =P16/(2*PI())*100 -> 0
B19: 모형의 질량관성모멘트 | D19: Io | E19: =E15*E23^2/((E21/E22)^2-1)/E18 -> 566.10038 | F19: kgcm2/m | L19: SC B | N19: =(2*$K$10*N15)/(1.225*($E$4/100)^2) -> 0.58819928 | O19: =(2*$K$10*O15)/(1.225*($E$4/100)^2) -> 0 | P19: =(2*$K$10*P15)/(1.225*($E$4/100)^2) -> 0
B20: (모형+추가질량)의 질량관성모멘트 | D20: I | E20: =-E15*E23^2/((E22/E21)^2-1)/E18 -> 666.69333 | F20: kgcm2/m | L20: SC T | N20: =(2*$L$24*N16)/(1.225*($E$4/100)^2) -> 108.97974 | O20: =(2*$L$24*O16)/(1.225*($E$4/100)^2) -> 0 | P20: =(2*$L$24*P16)/(1.225*($E$4/100)^2) -> 0
B21: 모형의 비틀림진동수 | D21: Fto | E21: 2.5406 | F21: Hz | N21: =(($K$11-N19)/$K$11)*100 -> 30.068023 | O21: =(($K$11-O19)/$K$11)*100 -> 100 | P21: =(($K$11-P19)/$K$11)*100 -> 100
B22: 질량 추가시 비틀림진동수 | D22: Fta | E22: 2.3411 | F22: Hz | L22: 15 | N22: =(($K$12-N20)/$K$12)*100 -> 12.995298 | O22: =(($K$12-O20)/$K$12)*100 -> 100 | P22: =(($K$12-P20)/$K$12)*100 -> 100
B23: 중심부터 거리 | D23: R | E23: 16 | F23: cm | H23: 목표거리 | I23: =SQRT((E6-E19)/E15*E18) -> 14.718113 | K23: 562.80866 | L23: =K8*L22^2*(1/0.85) -> 88.411765
D24: 실험진동수(연직) | E24: 1.4358 | F24: =((E7-E24)/E7)*100 -> -0.38453471 | L24: =K23+L23 -> 651.22042 | M24: =(((E6-L24))/E6)*100 -> -5.2372515e-14
D25: 실험진동수(비틀림) | E25: 3.1084 | F25: =((E8-E25)/E8)*100 -> -0.15465911 | G25: =(((E6-E20))/E6)*100 -> -2.3759852
E26: 목표진동수비 | F26: =E8/E7 -> 2.1698944 | G26: =(((F26-F27))/F26)*100 -> 0.22899504 | H26: 감쇠
B27: 스프링간격 | C27: 20.5cm | E27: 실험진동수비 | F27: =E25/E24 -> 2.1649255 | H27: =E4/200*10 -> 2 | R27: =R28-6000 -> 32541 | S27: =S28-3000 -> 17173
B28: 댐퍼간격 | C28: 0cm | F28: =E24*F26 -> 3.1155344 | H28: =TAN(RADIANS(0.5))*(E4/2)*10 -> 1.7453736 | I28: 실험풍속 | J28: =40*SQRT(1/$D$1)*(E24/E7) -> 40.153814 | K28: 연직 | R28: 38541 | S28: 20173
B29: 센서간격 | C29: 13cm | F29: =E25/F26 -> 1.4325121 | J29: =40*SQRT(1/$D$1)*(E25/E8) -> 40.061864 | K29: 비틀림 | R29: =R28+6000 -> 44541 | S29: =S28+3000 -> 23173
B30: 스프링 | C30: 상, NO20(강선)
C31: 하, 없음
C32: 선경, 직경, 길이
